<?xml version="1.0"?>
<robot name="rover" xmlns:xacro="http://www.ros.org/wiki/xacro">
  <!-- Macros-->
  <!-- colors -->
  <material name="green">
    <color rgba="0.0 1.0 0.0 1.0"/>
  </material>
  <material name="black">
    <color rgba="1 1 1 1.0"/>
  </material>
  <material name="red">
    <color rgba="1 0 0 1.0"/>
  </material>

  <!-- body inertia -->
  <xacro:property name="body_length" value="0.22"/>
  <xacro:property name="body_width" value="0.15"/>
  <xacro:property name="body_height" value="0.1"/>
  <xacro:property name="body_mass" value="2.0"/>
  <xacro:property name="cube_xx" value="${(1/12) * body_mass * (body_width * body_width + body_length * body_length)}"/>
  <xacro:property name="cube_yy" value="${(1/12) * body_mass * (body_height * body_height + body_length * body_length)}"/>
  <xacro:property name="cube_zz" value="${(1/12) * body_mass * (body_height * body_height + body_width * body_width)}"/>

  <!-- bogie and rocker lengths and inertia -->
  <xacro:property name="rocker_to_bogie" value="0.145"/><!-- 0.145-->
  <xacro:property name="bogie_length" value="0.2"/><!-- 0.16-->
  <xacro:property name="bogie_mass" value="0.057"/>
  <xacro:property name="bogie_inertia" value="${(1/12) * bogie_mass * bogie_length ** 2}"/>
  <xacro:property name="rocker_to_back_wheel" value="-0.135"/><!-- -0.095-->

  <!-- wheel inertia -->
  <xacro:property name="wheel_radius" value="0.057" />
  <xacro:property name="wheel_length" value="0.03"  />
  <xacro:property name="wheel_mass" value="0.37"  />
  <xacro:property name="wheel_zz" value="${0.5 * wheel_mass * (wheel_radius ** 2)}"/>
  <xacro:property name="wheel_xx_yy" value="${wheel_mass / 12.0 * (3.0 * wheel_radius ** 2) + wheel_length ** 2}"/>
  
  <xacro:property name="front_wheel_mass" value="0.55"  />
  <xacro:property name="mid_wheel_mass" value="0.7"  />
  <xacro:property name="back_wheel_mass" value="0.37"  />
  <xacro:property name="velocity_limit" value="10"/>

  <!-- links ###############################################################-->
  <link name="base_footprint" />
  <!-- robot house -->
  <link name="base_link">
    <!-- Visual properties of the link -->
    <visual>
      <geometry>
        <box size="0.22 0.15 0.1" />
      </geometry>
      <origin xyz="0 0 0" rpy="0 0 0"/>
      <material name="green"/>
    </visual>
    <!-- Collision properties of the link -->
    <collision>
      <geometry>
        <box size="0.22 0.15 0.1" />
      </geometry>
      <origin xyz="0 0 0" rpy="0 0 0"/>
    </collision>
    <inertial>
      <mass value="${body_mass}"/>
      <origin xyz="0 0 -0.03" rpy="0 0 0"/>
      <inertia ixx="${cube_xx}" ixy="0.0" ixz="0.0" iyy="${cube_yy}" iyz="0.0" izz="${cube_zz}"/>
    </inertial>
  </link>

  <xacro:macro name="rocker" params="name">
    <link name="${name}">
      <visual>
        <geometry>
          <cylinder radius="0.015" length="0.05"/>
        </geometry>
        <origin xyz="0 0 0" rpy="1.57 0 0"/>
        <material name="red"/>
      </visual>
      <collision>
        <geometry>
          <cylinder radius="0.015" length="0.05"/>
        </geometry>
        <origin xyz="0 0 0" rpy="1.57 0 0"/>
      </collision>
      <inertial>
        <mass value="0.2"/>
        <inertia ixx="0.0001" ixy="0.0" ixz="0.0" iyy="0.0001" iyz="0.0" izz="0.0001"/>
      </inertial>
    </link>
  </xacro:macro>
  <xacro:rocker name="rocker_left"/>
  <xacro:rocker name="rocker_right"/>

  <xacro:macro name="bogie" params="name">
    <link name="${name}">
      <visual>
        <geometry>
          <cylinder radius="0.015" length="${bogie_length}"/>
        </geometry>
        <origin xyz="0 0 0" rpy="0 1.57 0"/>
        <material name="black"/>
      </visual>
      <collision>
        <geometry>
          <cylinder radius="0.015" length="${bogie_length}"/>
        </geometry>
        <origin xyz="0 0 0" rpy="0 1.57 0"/>
      </collision>
      <inertial>
        <mass value="${bogie_mass}"/>
        <inertia ixx="${bogie_inertia}" ixy="0.0" ixz="0.0" iyy="0.0" iyz="0.0" izz="${bogie_inertia}"/>
      </inertial>
    </link>
  </xacro:macro>
  <xacro:bogie name="bogie_left"/>
  <xacro:bogie name="bogie_right"/>

  <xacro:macro name="wheel" params="name mass">
    <link name="${name}">
      <visual>
        <geometry>
          <mesh filename="file:///home/joshua/Desktop/rover_simulation/src/rover_description/meshes/wheel.stl" scale="0.001 0.001 0.001"/>
        </geometry>
        <origin xyz="0 -0.03 0" rpy="0 0 0"/>
        <material name="black"/>
      </visual>
      <collision>
        <geometry>
          <mesh filename="file:///home/joshua/Desktop/rover_simulation/src/rover_description/meshes/wheel.stl" scale="0.001 0.001 0.001"/>
        </geometry>
        <origin xyz="0 -0.03 0" rpy="0 0 0"/>
      </collision>
      <inertial>
        <mass value="${mass}"/>
        <inertia 
          ixx="${wheel_xx_yy}"
          ixy="0.0"
          ixz="0.0"
          iyy="${wheel_xx_yy}"
          iyz="0.0"
          izz="${wheel_zz}"/>
      </inertial>
    </link>
  </xacro:macro>
  <xacro:wheel name="bogie_left_wheel_front" mass="${front_wheel_mass}"/>
  <xacro:wheel name="bogie_left_wheel_back" mass="${mid_wheel_mass}"/>
  <xacro:wheel name="back_left_wheel" mass="${back_wheel_mass}"/>
  <xacro:wheel name="bogie_right_wheel_front" mass="${front_wheel_mass}"/>
  <xacro:wheel name="bogie_right_wheel_back" mass="${mid_wheel_mass}"/>
  <xacro:wheel name="back_right_wheel" mass="${back_wheel_mass}"/>

  <xacro:macro name="servo" params="name">
    <link name="${name}">
      <inertial>
        <mass value="0.018"/>
        <inertia ixx="0.0001" ixy="0.0" ixz="0.0" iyy="0.0001" iyz="0.0" izz="0.0001"/>
      </inertial>
    </link>
  </xacro:macro>
  <xacro:servo name="servo1"/>
  <xacro:servo name="servo2"/>
  <xacro:servo name="servo3"/>
  <xacro:servo name="servo4"/>
  <xacro:servo name="servo5"/>
  <xacro:servo name="servo6"/>

  <link name="referrence">
    <visual>
      <origin xyz="0.15 0.05 -0.115" rpy="0 0 3.14"/>
      <geometry>
        <mesh filename="file:///home/joshua/Desktop/rover_simulation/src/rover_description/meshes/rover.stl" scale="0.001 0.001 0.001"/>
      </geometry>
      <material name="example_material">
        <color rgba="0.8 0.8 0.8 0.4"/>
      </material>
    </visual>
  </link>

  <!-- joints ###########################################################################################3-->
     <!-- needed to visualise referrence -->
  <joint name="referrence" type="fixed">
    <parent link="base_link"/>
    <child link="referrence"/>
    <origin xyz="0 0 0" rpy="0 0 0"/>
  </joint>
   <joint name="base_joint" type="fixed">
      <parent link="base_footprint"/>
      <child link="base_link"/>
      <origin xyz="0 0 0.157"></origin>
   </joint>

  <!-- rocker_left -->
  <joint name="rocker_left_joint" type="revolute">
    <parent link="base_link"/>
    <child link="rocker_left"/>
    <origin xyz="-0.075 0.1 0.005" rpy="0 0 0"/>
    <axis xyz="0.0 1.0 0.0"/>
    <limit lower="-0.13" upper="0.13" effort="100" velocity="10"/>
  </joint>
  <!-- rocker_right -->
  <joint name="rocker_right_joint" type="revolute">
    <parent link="base_link"/>
    <child link="rocker_right"/>
    <origin xyz="-0.075 -0.1 0.005" rpy="0 0 0"/>
    <axis xyz="0.0 1.0 0.0"/>
    <mimic joint="rocker_left_joint" multiplier="-1.0"/>
    <limit lower="-0.13" upper="0.13" effort="100" velocity="10"/>
  </joint>
  <!-- bogie_left -->
  <joint name="bogie_left_joint" type="revolute">
    <parent link="rocker_left"/>
    <child link="bogie_left"/>
    <origin xyz="${rocker_to_bogie} 0.02 -0.055" rpy="0 0 0"/>
    <axis xyz="0.0 1.0 0.0"/>
    <limit lower="1.57" upper="-0.436332" effort="100" velocity="10"/>
  </joint>
  <joint name="bogie_left_wheel_front_joint" type="continuous">
    <parent link="bogie_left"/>
    <child link="bogie_left_wheel_front"/>
    <origin xyz="${bogie_length/2} 0 -0.065" rpy="0 0 0"/>
    <axis xyz="0.0 1.0 0.0"/>
    <limit effort="100" velocity="${velocity_limit}"/>
  </joint>
  <joint name="bogie_left_wheel_back_joint" type="continuous">
    <parent link="bogie_left"/>
    <child link="bogie_left_wheel_back"/>
    <origin xyz="-${bogie_length/2} 0 -0.065" rpy="0 0 0"/>
    <axis xyz="0.0 1.0 0.0"/>
    <limit effort="100" velocity="${velocity_limit}"/>
  </joint>

  <!-- bogie_right -->
  <joint name="bogie_right_joint" type="revolute">
    <parent link="rocker_right"/>
    <child link="bogie_right"/>
    <origin xyz="${rocker_to_bogie} -0.02 -0.055" rpy="0 0 0"/>
    <axis xyz="0.0 1.0 0.0"/>
    <limit lower="1.57" upper="-0.436332" effort="100" velocity="10"/><!-- -0.436332-->
  </joint>
  <joint name="bogie_right_wheel_front_joint" type="continuous">
    <parent link="bogie_right"/>
    <child link="bogie_right_wheel_front"/>
    <origin xyz="${bogie_length/2} 0 -0.065" rpy="0 0 0"/>
    <axis xyz="0.0 1.0 0.0"/>
    <limit effort="100" velocity="${velocity_limit}"/>
  </joint>
  <joint name="bogie_right_wheel_back_joint" type="continuous">
    <parent link="bogie_right"/>
    <child link="bogie_right_wheel_back"/>
    <origin xyz="-${bogie_length/2} 0 -0.065" rpy="0 0 0"/>
    <axis xyz="0.0 1.0 0.0"/>
    <limit effort="100" velocity="${velocity_limit}"/>
  </joint>

  <!-- back wheels -->
  <joint name="back_left_wheel_joint" type="continuous">
    <parent link="rocker_left"/>
    <child link="back_left_wheel"/>
    <origin xyz="${rocker_to_back_wheel} -0.02 -0.12" rpy="0 0 0"/>
    <axis xyz="0.0 1.0 0.0"/>
    <limit effort="100" velocity="${velocity_limit}"/>
  </joint>
  <joint name="back_right_wheel_joint" type="continuous">
    <parent link="rocker_right"/>
    <child link="back_right_wheel"/>
    <origin xyz="${rocker_to_back_wheel} -0.02 -0.12" rpy="0 0 0"/>
    <axis xyz="0.0 1.0 0.0"/>
    <limit effort="100" velocity="${velocity_limit}"/>
  </joint>

  <!-- Servo weight-->
  <joint name="servo1_joint" type="fixed">
    <parent link="bogie_left"/>
    <child link="servo1"/>
    <origin xyz="${bogie_length/2} 0 0" rpy="0 0 0"/>
  </joint>
  <joint name="servo2_joint" type="fixed">
    <parent link="bogie_right"/>
    <child link="servo2"/>
    <origin xyz="${bogie_length/2} 0 0" rpy="0 0 0"/>
  </joint>
  <joint name="servo3_joint" type="fixed">
    <parent link="bogie_left"/>
    <child link="servo3"/>
    <origin xyz="-${bogie_length/2} 0 0" rpy="0 0 0"/>
  </joint>
  <joint name="servo4_joint" type="fixed">
    <parent link="bogie_right"/>
    <child link="servo4"/>
    <origin xyz="-${bogie_length/2} 0 0" rpy="0 0 0"/>
  </joint>
  <joint name="servo5_joint" type="fixed">
    <parent link="base_link"/>
    <child link="servo5"/>
    <origin xyz="-0.20 0.12 -0.055" rpy="0 0 0"/>
  </joint>
  <joint name="servo6_joint" type="fixed">
    <parent link="base_link"/>
    <child link="servo6"/>
    <origin xyz="-0.20 -0.12 -0.055" rpy="0 0 0"/>
  </joint>
  <!-- transmission ####################################################### -->
  <ros2_control name="GazeboSystem" type="system">
    <hardware>
      <plugin>gazebo_ros2_control/GazeboSystem</plugin>
    </hardware>
  
    <!-- Left wheel 1 -->
    <joint name="bogie_left_wheel_front_joint">
      <command_interface name="effort">
        <param name="min">-1</param>
        <param name="max">1</param>
      </command_interface>
      <state_interface name="velocity"/>
      <state_interface name="effort"/>
    </joint>
  
    <!-- Left wheel 2 -->
    <joint name="bogie_left_wheel_back_joint">
      <command_interface name="effort">
        <param name="min">-1</param>
        <param name="max">1</param>
      </command_interface>
      <state_interface name="velocity"/>
      <state_interface name="effort"/>
    </joint>
  
    <!-- Left wheel 3 -->
    <joint name="back_left_wheel_joint">
      <command_interface name="effort">
        <param name="min">-1</param>
        <param name="max">1</param>
      </command_interface>
      <state_interface name="velocity"/>
      <state_interface name="effort"/>
    </joint>
  
    <!-- Right wheel 1 -->
    <joint name="bogie_right_wheel_front_joint">
      <command_interface name="effort">
        <param name="min">-1</param>
        <param name="max">1</param>
      </command_interface>
      <state_interface name="velocity"/>
      <state_interface name="effort"/>
    </joint>
  
    <!-- Right wheel 2 -->
    <joint name="bogie_right_wheel_back_joint">
      <command_interface name="effort">
        <param name="min">-1</param>
        <param name="max">1</param>
      </command_interface>
      <state_interface name="velocity"/>
      <state_interface name="effort"/>
    </joint>
  
    <!-- Right wheel 3 -->
    <joint name="back_right_wheel_joint">
      <command_interface name="effort">
        <param name="min">-1</param>
        <param name="max">1</param>
      </command_interface>
      <state_interface name="velocity"/>
      <state_interface name="effort"/>
    </joint>
  </ros2_control>
  

  <!-- gazebo plugin-->
  <gazebo>
    <!-- Joint state publisher -->
    <plugin filename="libgazebo_ros2_control.so" name="gazebo_ros2_control">
      <parameters>$(find rover_control)/config/effort_control.yaml</parameters>
    </plugin>
  </gazebo>
</robot>